Workbook

Sheet 04.05.2026
A1: SALES ORDER REPORT | K1: =TODAY() -> 46171
A2: Date | B2: Delivery Date | C2: Job Number | D2: SO Number | E2: Customer Ref. | F2: Customer | G2: Total | H2: Sales Rep | I2: Status | J2: Payment Status | K2: Details | L2: Planned Delivery Date
A3: 46120 | B3: 46146.328 | C3: FM3985 | D3: SO4510 | E3: 62048 | F3: Chabo & Joubert Air Conditioning (Pty) Ltd | G3: 50593.1 | H3: Sizwe Tshabalala | I3: Ready-Dispatch | J3: ACCOUNT - UP TO DATE | K3: UV250/1/6 c/w 0.18kW 960rpm 6pole 220V Single Phase Motor incl Bird Screen (Qty: 2), UV400/3/6 c/w 0.55kW 960rpm 6Pole 380V Motor incl Bird Screen (Qty: 1) | L3: =B3 -> 46146.328
A4: 46133 | B4: 46146.328 | C4: FM4008 | D4: SO4537 | E4: PO-0070 | F4: Duty Point Pty Ltd | G4: 28418.48 | H4: Mashudu Tshifularo | I4: Ready-Dispatch | J4: CASH SALE – PARTIAL | K4: MAXFLO 800/150/10 A c/w 4,00KW 4P 380V - PLATE AXIAL (Qty: 2) | L4: =B4 -> 46146.328
A5: 46136 | B5: 46146.328 | C5: FM4017 | D5: SO4546 | E5: PO145956 | F5: Howden Power a Div of Howden Africa (Pty) LTD | G5: 15437.6 | H5: Sizwe Tshabalala | I5: Ready-Dispatch | J5: ACCOUNT - UP TO DATE | K5: SCL-K03 MS-0.55kW-380V (Qty: 1) | L5: =B5 -> 46146.328
A6: 46111 | B6: 46171 | C6: FM3967 | D6: SO4492 | E6: PO260306 | F6: Alpha Air Ventilation Services | G6: 9014.21 | H6: Sizwe Tshabalala | I6: On Hold | K6: MAJAX-2 500 c/w 0,55KW 4P 380V (Qty: 1), 500 Diam Counter Flange (Qty: 2) | L6: =B6 -> 46171
A7: 46112 | B7: 46146.328 | C7: FM3974 | D7: SO4502 | E7: 210719 | F7: Kenmare Moma Processing (Mauritius) Limited | G7: 103711 | H7: Sizwe Tshabalala | I7: In Progress | J7: ACCOUNT - UP TO DATE | K7: SCL-K10 MS-11kW - Item no 28000234 (Qty: 1) | L7: =B7 -> 46146.328
A8: 46112 | B8: 46146.328 | C8: FM3997 | D8: SO4525 | E8: 211035 | F8: Kenmare Moma Processing (Mauritius) Limited | G8: 83433 | H8: Sizwe Tshabalala | I8: In Progress | J8: ACCOUNT - UP TO DATE | K8: SCL-K08 MS-7.5kW (Qty: 1) | L8: =B8 -> 46146.328
A9: 46119 | B9: 46146.328 | C9: FM3979 | D9: SO4506 | E9: 14264 | F9: Arta Masjinerie | G9: 58613.2 | H9: Simon Mokgola | I9: In Progress | J9: ACCOUNT - UP TO DATE | K9: 800 c/w 3.0Kw 4Pole 380V (Qty: 4) | L9: =B9 -> 46146.328
A10: 46133 | B10: 46146.328 | C10: FM4020 | D10: SO4549 | E10: nan | F10: Sulit Projects | G10: 1573.2 | H10: Mashudu Tshifularo | I10: In Progress | J10: CASH SALE - PAID | K10: RAD 125 (Qty: 1) | L10: =B10 -> 46146.328
A11: 46136 | B11: 46146.328 | C11: FM4016 | D11: SO4545 | E11: cash sale | F11: ZEFS More Vision | G11: 57647.2 | H11: Mashudu Tshifularo | I11: In Progress | J11: CASH SALE - PAID | K11: MAXFLO 500/150/10 A c/w 1,10KW 4P 380V (Qty: 4), 500 Diam Mounting Feet (Qty: 12), MAXFLO 560/150/10 A c/w 1,10KW 4P 380V (Qty: 2), 560 Diam Mounting Feet (Qty: 6), 315 to 560 NDA RED ANeoprene Floor Mounts (Qty: 36) | L11: =B11 -> 46146.328
A12: 46111 | B12: 46171 | C12: FM3990 | D12: SO4517 | E12: PO:0000426 | F12: Compu Cool (Pty) Ltd | G12: 169353.6 | H12: Mashudu Tshifularo | I12: On Hold | K12: UV710/3/6 (Qty: 6) | L12: =B12 -> 46171
A13: 46069 | B13: 46157 | C13: FM3841 | D13: SO4372 | E13: PO2213 | F13: Hucra Fans | G13: 379993.35 | H13: Sales Agent Hucra Fans | I13: In Progress | J13: ACCOUNT - UP TO DATE | K13: SCL K11 MS - 11.0kW - 525V (Qty: 3) | L13: =B13 -> 46157
A14: 46077 | B14: 46157 | C14: FM3874 | D14: SO4404 | E14: PO2174 | F14: ITD North Pty Ltd | G14: 94247.1 | H14: Mashudu Tshifularo | I14: In Progress | J14: CASH SALE – PARTIAL | K14: RDH 710 K2 - Nicotra Fan (Qty: 1) | L14: =B14 -> 46157
F15: Total Value (All): | G15: =SUM(G3:G14) -> 1052035
F17: BREAKDOWN
F18: Cash Sale (May): | G18: =SUMIFS(G3:G14, J3:J14, "*CASH SALE*", L3:L14, ">="&EOMONTH(TODAY(),-1)+1, L3:L14, "<="&EOMONTH(TODAY(),0)) -> 181885.98 | I18: Cash Sale (June): | J18: =SUMIFS(G3:G14, J3:J14, "*CASH SALE*", L3:L14, ">="&EOMONTH(TODAY(),0)+1, L3:L14, "<="&EOMONTH(TODAY(),1)) -> 0
F19: Account (May): | G19: =SUMIFS(G3:G14, J3:J14, "*ACCOUNT*", L3:L14, ">="&EOMONTH(TODAY(),-1)+1, L3:L14, "<="&EOMONTH(TODAY(),0)) -> 691781.25 | I19: Account (June): | J19: =SUMIFS(G3:G14, J3:J14, "*ACCOUNT*", L3:L14, ">="&EOMONTH(TODAY(),0)+1, L3:L14, "<="&EOMONTH(TODAY(),1)) -> 0
A22: Date | B22: Delivery Date | C22: Job Number | D22: SO Number | E22: Customer Ref. | F22: Customer | G22: Total | H22: Sales Rep | I22: Status | J22: Payment Status | K22: Comments
A23: 46120 | B23: 46146.328 | C23: FM3985 | D23: SO4510 | E23: 62048 | F23: Chabo & Joubert Air Conditioning (Pty) Ltd | G23: 50593.1 | H23: Sizwe Tshabalala | I23: Ready-Dispatch | J23: ACCOUNT - UP TO DATE
A24: 46133 | B24: 46146.328 | C24: FM4008 | D24: SO4537 | E24: PO-0070 | F24: Duty Point Pty Ltd | G24: 28418.48 | H24: Mashudu Tshifularo | I24: Ready-Dispatch | J24: CASH SALE – PARTIAL | K24: Balance payment required prior to delivery/collection
A25: 46136 | B25: 46146.328 | C25: FM4017 | D25: SO4546 | E25: PO145956 | F25: Howden Power a Div of Howden Africa (Pty) LTD | G25: 15437.6 | H25: Sizwe Tshabalala | I25: Ready-Dispatch | J25: ACCOUNT - UP TO DATE | K25: Client to collect 28/04/2026 - Sizwe to advise
A26: 46111 | B26: 46171 | C26: FM3967 | D26: SO4492 | E26: PO260306 | F26: Alpha Air Ventilation Services | G26: 9014.21 | H26: Sizwe Tshabalala | I26: On Hold
A27: 46112 | B27: 46146.328 | C27: FM3974 | D27: SO4502 | E27: 210719 | F27: Kenmare Moma Processing (Mauritius) Limited | G27: 103711 | H27: Sizwe Tshabalala | I27: In Progress | J27: ACCOUNT - UP TO DATE
A28: 46112 | B28: 46146.328 | C28: FM3997 | D28: SO4525 | E28: 211035 | F28: Kenmare Moma Processing (Mauritius) Limited | G28: 83433 | H28: Sizwe Tshabalala | I28: In Progress | J28: ACCOUNT - UP TO DATE
A29: 46119 | B29: 46146.328 | C29: FM3979 | D29: SO4506 | E29: 14264 | F29: Arta Masjinerie | G29: 58613.2 | H29: Simon Mokgola | I29: In Progress | J29: ACCOUNT - UP TO DATE
A30: 46133 | B30: 46146.328 | C30: FM4020 | D30: SO4549 | E30: nan | F30: Sulit Projects | G30: 1573.2 | H30: Mashudu Tshifularo | I30: In Progress | J30: CASH SALE - PAID
A31: 46136 | B31: 46146.328 | C31: FM4016 | D31: SO4545 | E31: cash sale | F31: ZEFS More Vision | G31: 57647.2 | H31: Mashudu Tshifularo | I31: In Progress | J31: CASH SALE - PAID
F32: Due Today - Total: | G32: =SUM(G23:G31) -> 408440.99
F34: Ready-Dispatch: | G34: =SUMIFS(G3:G14, I3:I14, "*Ready*Dispatch*") -> 94449.18
A37: Recommended Print Range: A1:L39
A38: Suggested Date for Next Update: 05.05.2026

Sheet 05.05.2026
A1: SALES ORDER REPORT | K1: =TODAY() -> 46171
A2: Date | B2: Delivery Date | C2: Job Number | D2: SO Number | E2: Customer Ref. | F2: Customer | G2: Total | H2: Sales Rep | I2: Status | J2: Payment Status | K2: Details | L2: Planned Delivery Date
A3: 46120 | B3: 46147.402 | C3: FM3985 | D3: SO4510 | E3: 62048 | F3: Chabo & Joubert Air Conditioning (Pty) Ltd | G3: 50593.1 | H3: Sizwe Tshabalala | I3: Ready-Dispatch | J3: ACCOUNT - UP TO DATE | K3: UV250/1/6 c/w 0.18kW 960rpm 6pole 220V Single Phase Motor incl Bird Screen (Qty: 2), UV400/3/6 c/w 0.55kW 960rpm 6Pole 380V Motor incl Bird Screen (Qty: 1) | L3: =B3 -> 46147.402
A4: 46136 | B4: 46147.402 | C4: FM4017 | D4: SO4546 | E4: PO145956 | F4: Howden Power a Div of Howden Africa (Pty) LTD | G4: 15437.6 | H4: Sizwe Tshabalala | I4: Ready-Dispatch | J4: ACCOUNT - UP TO DATE | K4: SCL-K03 MS-0.55kW-380V (Qty: 1) | L4: =B4 -> 46147.402
A5: 46133 | B5: 46147.402 | C5: FM4020 | D5: SO4549 | E5: nan | F5: Sulit Projects | G5: 1573.2 | H5: Mashudu Tshifularo | I5: Ready-Dispatch | J5: CASH SALE - PAID | K5: RAD 125 (Qty: 1) | L5: =B5 -> 46147.402
A6: 46146 | B6: 46149 | C6: FM4025 | D6: SO4559 | E6: PO0000475 | F6: Compu Cool (Pty) Ltd | G6: 11429.61 | H6: Mashudu Tshifularo | I6: In Progress | J6: ACCOUNT - UP TO DATE | K6: MAXFLO 710/150/10 A c/w 2,20KW 4P 380V (Qty: 1) | L6: =B6 -> 46149
A7: 46111 | B7: 46171 | C7: FM3990 | D7: SO4517 | E7: PO:0000426 | F7: Compu Cool (Pty) Ltd | G7: 169353.6 | H7: Mashudu Tshifularo | I7: On Hold | J7: ACCOUNT - UP TO DATE | K7: UV710/3/6 (Qty: 6) | L7: =B7 -> 46171
A8: 46112 | B8: 46150 | C8: FM3974 | D8: SO4502 | E8: 210719 | F8: Kenmare Moma Processing (Mauritius) Limited | G8: 103711 | H8: Sizwe Tshabalala | I8: In Progress | J8: ACCOUNT - UP TO DATE | K8: SCL-K10 MS-11kW - Item no 28000234 (Qty: 1) | L8: =B8 -> 46150
A9: 46112 | B9: 46150 | C9: FM3997 | D9: SO4525 | E9: 211035 | F9: Kenmare Moma Processing (Mauritius) Limited | G9: 83433 | H9: Sizwe Tshabalala | I9: In Progress | J9: ACCOUNT - UP TO DATE | K9: SCL-K08 MS-7.5kW (Qty: 1) | L9: =B9 -> 46150
A10: 46069 | B10: 46157 | C10: FM3841 | D10: SO4372 | E10: PO2213 | F10: Hucra Fans | G10: 379993.35 | H10: Sales Agent Hucra Fans | I10: In Progress | J10: ACCOUNT - UP TO DATE | K10: SCL K11 MS - 11.0kW - 525V (Qty: 3) | L10: =B10 -> 46157
A11: 46077 | B11: 46157 | C11: FM3874 | D11: SO4404 | E11: PO2174 | F11: ITD North Pty Ltd | G11: 94247.1 | H11: Mashudu Tshifularo | I11: In Progress | J11: CASH SALE – PARTIAL | K11: RDH 710 K2 - Nicotra Fan (Qty: 1) | L11: =B11 -> 46157
A12: 46111 | B12: 46171 | C12: FM3967 | D12: SO4492 | E12: PO260306 | F12: Alpha Air Ventilation Services | G12: 9014.21 | H12: Sizwe Tshabalala | I12: On Hold | J12: =IFERROR(VLOOKUP(D12, '04.05.2026'!D:J, 7, FALSE), "") -> 0 | K12: MAJAX-2 500 c/w 0,55KW 4P 380V (Qty: 1), 500 Diam Counter Flange (Qty: 2) | L12: =B12 -> 46171
A13: 46057 | B13: 46171 | C13: Pending | D13: SO4558 | E13: FMTA4398-Thabakgolo | F13: Oribi Air CC | G13: 427841.4 | H13: Mashudu Tshifularo | I13: Pending | J13: =IFERROR(VLOOKUP(D13, '04.05.2026'!D:J, 7, FALSE), "") | K13: LINEO 250 QUIET-5.1.1 (Qty: 24), LINEO 315 QUIET-5.6.1 (Qty: 12) | L13: =B13 -> 46171
A14: 46128 | B14: 46171 | C14: Pending | D14: SO4554 | E14: FMTA4599 | F14: Matla Solution Group | G14: 82900.05 | H14: Mashudu Tshifularo | I14: Pending | J14: =IFERROR(VLOOKUP(D14, '04.05.2026'!D:J, 7, FALSE), "") | K14: LINEO 315 QUIET - EF 1 (Qty: 1), LINEO 250 QUIET - EF 2 (Qty: 1), LINEO 200 QUIET - EF 3 (Qty: 1), KDAXIS 200 - EF 4 (Qty: 1), KDAXIS 200 - EF 5 (Qty: 1), MAXFLO 630/250/14 A c/w 1,10KW 4P 380V - FA 1 (Qty: 1), 630 Diam Silencer 1.5D Podded (Qty: 2), 630 Diam Counter Flange (Qty: 2), 630 Diam Mounting Feet (Qty: 4), 630 to 1000 NDB GREEN Neoprene Floor Mounts (Qty: 8), MAXFLO 710/250/14 A c/w 1,10KW 4P 380V - FA 2 (Qty: 1), 710 Diam Silencer 1.5D Podded (Qty: 2), 710 Diam Counter Flange (Qty: 2), 710 Diam Mounting Feet (Qty: 4), 630 to 1000 NDB GREEN Neoprene Floor Mounts (Qty: 8) | L14: =B14 -> 46171
A15: 46142 | B15: 46171 | C15: Pending | D15: SO4552 | E15: nan | F15: Neobionomics Services Pty Ltd | G15: 13711.09 | H15: Sizwe Tshabalala | I15: Pending | J15: =IFERROR(VLOOKUP(D15, '04.05.2026'!D:J, 7, FALSE), "") | K15: MAJAX-2 630 c/w 0,75KW 4P 380V (Qty: 1) | L15: =B15 -> 46171
A16: 46142 | B16: 46171 | C16: Pending | D16: SO4556 | E16: Constitutional Hill | F16: LJ Trading & Projects (Pty) Ltd | G16: 554227.55 | H16: Simon Mokgola | I16: Pending | J16: =IFERROR(VLOOKUP(D16, '04.05.2026'!D:J, 7, FALSE), "") | K16: Constitutional Hill (Qty: 1) | L16: =B16 -> 46171
A17: 46142 | B17: 46171 | C17: Pending | D17: SO4557 | E17: nan | F17: Vigeta Pty Ltd | G17: 204447 | H17: Simon Mokgola | I17: Pending | J17: =IFERROR(VLOOKUP(D17, '04.05.2026'!D:J, 7, FALSE), "") | K17: 630 Diam Vertical Discharge BASE c/w 2.2kW 4P 380V (Qty: 10) | L17: =B17 -> 46171
A18: 46142 | B18: 46171 | C18: Pending | D18: SO4553 | E18: FMTA4519 | F18: ST AIR SERVICES AND MAINTENANCE (PTY) LTD | G18: 426010.6 | H18: Simon Mokgola | I18: Pending | J18: =IFERROR(VLOOKUP(D18, '04.05.2026'!D:J, 7, FALSE), "") | K18: Mimosa Mall Office Park (Qty: 1) | L18: =B18 -> 46171
F19: Total Value (All): | G19: =SUM(G3:G18) -> 2627923.5
F21: BREAKDOWN
F22: Cash Sale (May): | G22: =SUMIFS(G3:G18, J3:J18, "*CASH SALE*", L3:L18, ">="&EOMONTH(TODAY(),-1)+1, L3:L18, "<="&EOMONTH(TODAY(),0)) -> 95820.3 | I22: Cash Sale (June): | J22: =SUMIFS(G3:G18, J3:J18, "*CASH SALE*", L3:L18, ">="&EOMONTH(TODAY(),0)+1, L3:L18, "<="&EOMONTH(TODAY(),1)) -> 0
F23: Account (May): | G23: =SUMIFS(G3:G18, J3:J18, "*ACCOUNT*", L3:L18, ">="&EOMONTH(TODAY(),-1)+1, L3:L18, "<="&EOMONTH(TODAY(),0)) -> 813951.26 | I23: Account (June): | J23: =SUMIFS(G3:G18, J3:J18, "*ACCOUNT*", L3:L18, ">="&EOMONTH(TODAY(),0)+1, L3:L18, "<="&EOMONTH(TODAY(),1)) -> 0
A26: Date | B26: Delivery Date | C26: Job Number | D26: SO Number | E26: Customer Ref. | F26: Customer | G26: Total | H26: Sales Rep | I26: Status | J26: Payment Status | K26: Comments
A27: 46120 | B27: 46147.402 | C27: FM3985 | D27: SO4510 | E27: 62048 | F27: Chabo & Joubert Air Conditioning (Pty) Ltd | G27: 50593.1 | H27: Sizwe Tshabalala | I27: Ready-Dispatch | J27: ACCOUNT - UP TO DATE | K27: Ready for collection 30/04/2026 - ST to advise
A28: 46133 | B28: 46147.402 | C28: FM4020 | D28: SO4549 | E28: nan | F28: Sulit Projects | G28: 1573.2 | H28: Mashudu Tshifularo | I28: Ready-Dispatch | J28: CASH SALE - PAID | K28: Invoiced - Ready for collection 04/05/2026 - MT to Advise
A29: 46136 | B29: 46147.402 | C29: FM4017 | D29: SO4546 | E29: PO145956 | F29: Howden Power a Div of Howden Africa (Pty) LTD | G29: 15437.6 | H29: Sizwe Tshabalala | I29: Ready-Dispatch | J29: ACCOUNT - UP TO DATE | K29: Client to collect 28/04/2026 - ST to advise
F30: Due Today - Total: | G30: =SUM(G27:G29) -> 67603.9
F32: Ready-Dispatch: | G32: =SUMIFS(G3:G18, I3:I18, "*Ready*Dispatch*") -> 67603.9

Sheet 06.05.2026
A1: SALES ORDER REPORT | K1: =TODAY() -> 46171
A2: Date | B2: Delivery Date | C2: Job Number | D2: SO Number | E2: Customer Ref. | F2: Customer | G2: Total | H2: Sales Rep | I2: Status | J2: Payment Status | K2: Details | L2: Planned Delivery Date
A3: 46136 | B3: 46148.4 | C3: FM4017 | D3: SO4546 | E3: PO145956 | F3: Howden Power a Div of Howden Africa (Pty) LTD | G3: 15437.6 | H3: Sizwe Tshabalala | I3: Ready-Dispatch | J3: ACCOUNT - UP TO DATE | K3: SCL-K03 MS-0.55kW-380V (Qty: 1) | L3: =B3 -> 46148.4
A4: 46146 | B4: 46149 | C4: FM4025 | D4: SO4559 | E4: PO0000475 | F4: Compu Cool (Pty) Ltd | G4: 11429.61 | H4: Mashudu Tshifularo | I4: In Progress | J4: ACCOUNT - UP TO DATE | K4: MAXFLO 710/150/10 A c/w 2,20KW 4P 380V (Qty: 1) | L4: =B4 -> 46149
A5: 46069 | B5: 46170 | C5: FM3841 | D5: SO4372 | E5: PO2213 | F5: Hucra Fans | G5: 379993.35 | H5: Sales Agent Hucra Fans | I5: In Progress | J5: ACCOUNT - UP TO DATE | K5: SCL K11 MS - 11.0kW - 525V (Qty: 3) | L5: =B5 -> 46170
A6: 46077 | B6: 46170 | C6: FM3874 | D6: SO4404 | E6: PO2174 | F6: ITD North Pty Ltd | G6: 94247.1 | H6: Mashudu Tshifularo | I6: In Progress | J6: CASH SALE – PARTIAL | K6: RDH 710 K2 - Nicotra Fan (Qty: 1) | L6: =B6 -> 46170
A7: 46057 | B7: 46171 | C7: Pending | D7: SO4558 | E7: FMTA4398-Thabakgolo | F7: Oribi Air CC | G7: 427841.4 | H7: Mashudu Tshifularo | I7: Pending | J7: =IFERROR(VLOOKUP(D7, '05.05.2026'!D:J, 7, FALSE), "") | K7: LINEO 250 QUIET-5.1.1 (Qty: 24), LINEO 315 QUIET-5.6.1 (Qty: 12) | L7: =B7 -> 46171
A8: 46111 | B8: 46171 | C8: FM3967 | D8: SO4492 | E8: PO260306 | F8: Alpha Air Ventilation Services | G8: 9014.21 | H8: Sizwe Tshabalala | I8: On Hold | J8: =IFERROR(VLOOKUP(D8, '05.05.2026'!D:J, 7, FALSE), "") -> 0 | K8: MAJAX-2 500 c/w 0,55KW 4P 380V (Qty: 1), 500 Diam Counter Flange (Qty: 2) | L8: =B8 -> 46171
A9: 46111 | B9: 46171 | C9: FM3990 | D9: SO4517 | E9: PO:0000426 | F9: Compu Cool (Pty) Ltd | G9: 169353.6 | H9: Mashudu Tshifularo | I9: On Hold | J9: =IFERROR(VLOOKUP(D9, '05.05.2026'!D:J, 7, FALSE), "") -> ACCOUNT - UP TO DATE | K9: UV710/3/6 (Qty: 6) | L9: =B9 -> 46171
A10: 46128 | B10: 46171 | C10: Pending | D10: SO4554 | E10: FMTA4599 | F10: Matla Solution Group | G10: 82900.05 | H10: Mashudu Tshifularo | I10: Pending | J10: =IFERROR(VLOOKUP(D10, '05.05.2026'!D:J, 7, FALSE), "") | K10: LINEO 315 QUIET - EF 1 (Qty: 1), LINEO 250 QUIET - EF 2 (Qty: 1), LINEO 200 QUIET - EF 3 (Qty: 1), KDAXIS 200 - EF 4 (Qty: 1), KDAXIS 200 - EF 5 (Qty: 1), MAXFLO 630/250/14 A c/w 1,10KW 4P 380V - FA 1 (Qty: 1), 630 Diam Silencer 1.5D Podded (Qty: 2), 630 Diam Counter Flange (Qty: 2), 630 Diam Mounting Feet (Qty: 4), 630 to 1000 NDB GREEN Neoprene Floor Mounts (Qty: 8), MAXFLO 710/250/14 A c/w 1,10KW 4P 380V - FA 2 (Qty: 1), 710 Diam Silencer 1.5D Podded (Qty: 2), 710 Diam Counter Flange (Qty: 2), 710 Diam Mounting Feet (Qty: 4), 630 to 1000 NDB GREEN Neoprene Floor Mounts (Qty: 8) | L10: =B10 -> 46171
A11: 46142 | B11: 46171 | C11: Pending | D11: SO4552 | E11: nan | F11: Neobionomics Services Pty Ltd | G11: 13711.09 | H11: Sizwe Tshabalala | I11: Pending | J11: =IFERROR(VLOOKUP(D11, '05.05.2026'!D:J, 7, FALSE), "") | K11: MAJAX-2 630 c/w 0,75KW 4P 380V (Qty: 1) | L11: =B11 -> 46171
A12: 46142 | B12: 46171 | C12: Pending | D12: SO4556 | E12: Constitutional Hill | F12: LJ Trading & Projects (Pty) Ltd | G12: 554227.55 | H12: Simon Mokgola | I12: Pending | J12: =IFERROR(VLOOKUP(D12, '05.05.2026'!D:J, 7, FALSE), "") | K12: Constitutional Hill (Qty: 1) | L12: =B12 -> 46171
A13: 46142 | B13: 46171 | C13: Pending | D13: SO4557 | E13: nan | F13: Vigeta Pty Ltd | G13: 204447 | H13: Simon Mokgola | I13: Pending | J13: =IFERROR(VLOOKUP(D13, '05.05.2026'!D:J, 7, FALSE), "") | K13: 630 Diam Vertical Discharge BASE c/w 2.2kW 4P 380V (Qty: 10) | L13: =B13 -> 46171
A14: 46142 | B14: 46171 | C14: Pending | D14: SO4553 | E14: FMTA4519 | F14: ST AIR SERVICES AND MAINTENANCE (PTY) LTD | G14: 426010.6 | H14: Simon Mokgola | I14: Pending | J14: =IFERROR(VLOOKUP(D14, '05.05.2026'!D:J, 7, FALSE), "") | K14: Mimosa Mall Office Park (Qty: 1) | L14: =B14 -> 46171
A15: 46112 | B15: 46293 | C15: FM3974 | D15: SO4502 | E15: 210719 | F15: Kenmare Moma Processing (Mauritius) Limited | G15: 103711 | H15: Sizwe Tshabalala | I15: In Progress | J15: ACCOUNT - UP TO DATE | K15: SCL-K10 MS-11kW - Item no 28000234 (Qty: 1) | L15: =B15 -> 46293
A16: 46112 | B16: 46293 | C16: FM3997 | D16: SO4525 | E16: 211035 | F16: Kenmare Moma Processing (Mauritius) Limited | G16: 83433 | H16: Sizwe Tshabalala | I16: In Progress | J16: ACCOUNT - UP TO DATE | K16: SCL-K08 MS-7.5kW (Qty: 1) | L16: =B16 -> 46293
F17: Total Value (All): | G17: =SUM(G3:G16) -> 2575757.2
F19: BREAKDOWN
F20: Cash Sale (May): | G20: =SUMIFS(G3:G16, J3:J16, "*CASH SALE*", L3:L16, ">="&EOMONTH(TODAY(),-1)+1, L3:L16, "<="&EOMONTH(TODAY(),0)) -> 94247.1 | I20: Cash Sale (June): | J20: =SUMIFS(G3:G16, J3:J16, "*CASH SALE*", L3:L16, ">="&EOMONTH(TODAY(),0)+1, L3:L16, "<="&EOMONTH(TODAY(),1)) -> 0
F21: Account (May): | G21: =SUMIFS(G3:G16, J3:J16, "*ACCOUNT*", L3:L16, ">="&EOMONTH(TODAY(),-1)+1, L3:L16, "<="&EOMONTH(TODAY(),0)) -> 576214.16 | I21: Account (June): | J21: =SUMIFS(G3:G16, J3:J16, "*ACCOUNT*", L3:L16, ">="&EOMONTH(TODAY(),0)+1, L3:L16, "<="&EOMONTH(TODAY(),1)) -> 0
A24: Date | B24: Delivery Date | C24: Job Number | D24: SO Number | E24: Customer Ref. | F24: Customer | G24: Total | H24: Sales Rep | I24: Status | J24: Payment Status | K24: Comments
A25: 46136 | B25: 46148.4 | C25: FM4017 | D25: SO4546 | E25: PO145956 | F25: Howden Power a Div of Howden Africa (Pty) LTD | G25: 15437.6 | H25: Sizwe Tshabalala | I25: Ready-Dispatch | J25: ACCOUNT - UP TO DATE | K25: Client to collect 28/04/2026 - ST to advise
F26: Due Today - Total: | G26: =SUM(G25:G25) -> 15437.6
F28: Ready-Dispatch: | G28: =SUMIFS(G3:G16, I3:I16, "*Ready*Dispatch*") -> 15437.6

Sheet 07.05.2026
A1: SALES ORDER REPORT | K1: =TODAY() -> 46171
A2: Date | B2: Delivery Date | C2: Job Number | D2: SO Number | E2: Customer Ref. | F2: Customer | G2: Total | H2: Sales Rep | I2: Status | J2: Payment Status | K2: Details | L2: Planned Delivery Date
A3: 46136 | B3: 46149.522 | C3: FM4017 | D3: SO4546 | E3: PO145956 | F3: Howden Power a Div of Howden Africa (Pty) LTD | G3: 15437.6 | H3: Sizwe Tshabalala | I3: In Progress | J3: ACCOUNT - UP TO DATE | K3: SCL-K03 MS-0.55kW-380V (Qty: 1) | L3: =B3 -> 46149.522
A4: 46142 | B4: 46171 | C4: Pending | D4: SO4556 | E4: Constitutional Hill | F4: LJ Trading & Projects (Pty) Ltd | G4: 554227.55 | H4: Simon Mokgola | I4: Pending | K4: Constitutional Hill (Qty: 1) | L4: =B4 -> 46171
A5: 46142 | B5: 46149.522 | C5: FM4031 | D5: SO4565 | E5: POAM26058144 | F5: Allbro Industries (PTY) Ltd | G5: 19154.4 | H5: Sizwe Tshabalala | I5: In Progress | J5: CASH SALE - PAID | K5: HV 7 c/w 0.45kw 6P 380v (Qty: 2), WEATHER LOUVRE 800(W)*800(H) HS NA (Qty: 2) | L5: =B5 -> 46149.522
A6: 46146 | B6: 46149.522 | C6: FM4025 | D6: SO4559 | E6: PO0000475 | F6: Compu Cool (Pty) Ltd | G6: 11429.61 | H6: Mashudu Tshifularo | I6: In Progress | J6: ACCOUNT - UP TO DATE | K6: MAXFLO 710/150/10 A c/w 2,20KW 4P 380V (Qty: 1) | L6: =B6 -> 46149.522
A7: 46148 | B7: 46157 | C7: FM4032 | D7: SO4566 | E7: FMTA4618 | F7: Breezeair Technical Services | G7: 13174.4 | H7: Mashudu Tshifularo | I7: In Progress | J7: CASH SALE - PAID | K7: MAXFLO 560/250/14 A c/w 1,10KW 4P 380V (Qty: 1), 560 Diam Counter Flange (Qty: 2), 560 Diam Mounting Feet (Qty: 4), 315 to 560 NDA RED ANeoprene Floor Mounts (Qty: 8) | L7: =B7 -> 46157
A8: 46077 | B8: 46169 | C8: FM3874 | D8: SO4404 | E8: PO2174 | F8: ITD North Pty Ltd | G8: 94247.1 | H8: Mashudu Tshifularo | I8: In Progress | J8: CASH SALE – PARTIAL | K8: RDH 710 K2 - Nicotra Fan (Qty: 1) | L8: =B8 -> 46169
A9: 46069 | B9: 46170 | C9: FM3841 | D9: SO4372 | E9: PO2213 | F9: Hucra Fans | G9: 379993.35 | H9: Sales Agent Hucra Fans | I9: In Progress | J9: ACCOUNT - UP TO DATE | K9: SCL K11 MS - 11.0kW - 525V (Qty: 3) | L9: =B9 -> 46170
A10: 46112 | B10: 46170 | C10: FM3974 | D10: SO4502 | E10: 210719 | F10: Kenmare Moma Processing (Mauritius) Limited | G10: 103711 | H10: Sizwe Tshabalala | I10: In Progress | J10: ACCOUNT - UP TO DATE | K10: SCL-K10 MS-11kW - Item no 28000234 (Qty: 1) | L10: =B10 -> 46170
A11: 46112 | B11: 46170 | C11: FM3997 | D11: SO4525 | E11: 211035 | F11: Kenmare Moma Processing (Mauritius) Limited | G11: 83433 | H11: Sizwe Tshabalala | I11: In Progress | J11: ACCOUNT - UP TO DATE | K11: SCL-K08 MS-7.5kW (Qty: 1) | L11: =B11 -> 46170
A12: 46057 | B12: 46171 | C12: Pending | D12: SO4558 | E12: FMTA4398-Thabakgolo | F12: Oribi Air CC | G12: 427841.4 | H12: Mashudu Tshifularo | I12: Pending | K12: LINEO 250 QUIET-5.1.1 (Qty: 24), LINEO 315 QUIET-5.6.1 (Qty: 12) | L12: =B12 -> 46171
A13: 46111 | B13: 46171 | C13: FM3967 | D13: SO4492 | E13: PO260306 | F13: Alpha Air Ventilation Services | G13: 9014.21 | H13: Sizwe Tshabalala | I13: Pending | K13: MAJAX-2 500 c/w 0,55KW 4P 380V (Qty: 1), 500 Diam Counter Flange (Qty: 2) | L13: =B13 -> 46171
A14: 46111 | B14: 46171 | C14: FM3990 | D14: SO4517 | E14: PO:0000426 | F14: Compu Cool (Pty) Ltd | G14: 169353.6 | H14: Mashudu Tshifularo | I14: Pending | K14: UV710/3/6 (Qty: 6) | L14: =B14 -> 46171
A15: 46128 | B15: 46171 | C15: Pending | D15: SO4554 | E15: FMTA4599 | F15: Matla Solution Group | G15: 82900.05 | H15: Mashudu Tshifularo | I15: Pending | K15: LINEO 315 QUIET - EF 1 (Qty: 1), LINEO 250 QUIET - EF 2 (Qty: 1), LINEO 200 QUIET - EF 3 (Qty: 1), KDAXIS 200 - EF 4 (Qty: 1), KDAXIS 200 - EF 5 (Qty: 1), MAXFLO 630/250/14 A c/w 1,10KW 4P 380V - FA 1 (Qty: 1), 630 Diam Silencer 1.5D Podded (Qty: 2), 630 Diam Counter Flange (Qty: 2), 630 Diam Mounting Feet (Qty: 4), 630 to 1000 NDB GREEN Neoprene Floor Mounts (Qty: 8), MAXFLO 710/250/14 A c/w 1,10KW 4P 380V - FA 2 (Qty: 1), 710 Diam Silencer 1.5D Podded (Qty: 2), 710 Diam Counter Flange (Qty: 2), 710 Diam Mounting Feet (Qty: 4), 630 to 1000 NDB GREEN Neoprene Floor Mounts (Qty: 8) | L15: =B15 -> 46171
A16: 46142 | B16: 46171 | C16: Pending | D16: SO4552 | E16: nan | F16: Neobionomics Services Pty Ltd | G16: 13711.09 | H16: Sizwe Tshabalala | I16: Pending | K16: MAJAX-2 630 c/w 0,75KW 4P 380V (Qty: 1) | L16: =B16 -> 46171
A17: 46142 | B17: 46171 | C17: Pending | D17: SO4553 | E17: FMTA4519 | F17: ST AIR SERVICES AND MAINTENANCE (PTY) LTD | G17: 426010.6 | H17: Simon Mokgola | I17: Pending | K17: Mimosa Mall Office Park (Qty: 1) | L17: =B17 -> 46171
A18: 46142 | B18: 46171 | C18: FM4036 | D18: SO4555 | E18: FM4035-FM4036 | F18: Michmat Projects | G18: 310411 | H18: Mashudu - R.O.A | I18: Pending | K18: MFAJAX-3 1250 c/w 45,00KW 4P 380V (Qty: 3), 1250 Diam Counter Flange (Qty: 6), 1250 Diam Mounting Feet (Qty: 6), 630 to 1000 NDB GREEN Neoprene Floor Mounts (Qty: 12), MAJAX-3 560 c/w 5,50KW 2P 380V (Qty: 2), 560 Diam Counter Flange (Qty: 4), 560 Diam Mounting Feet (Qty: 4), 315 to 560 NDA RED ANeoprene Floor Mounts (Qty: 8) | L18: =B18 -> 46171
A19: 46142 | B19: 46171 | C19: Pending | D19: SO4557 | E19: nan | F19: Vigeta Pty Ltd | G19: 204447 | H19: Simon Mokgola | I19: Pending | K19: 630 Diam Vertical Discharge BASE c/w 2.2kW 4P 380V (Qty: 10) | L19: =B19 -> 46171
F20: Total Value (All): | G20: =SUM(G3:G19) -> 2918497
F22: BREAKDOWN
F23: Cash Sale (May): | G23: =SUMIFS(G3:G19, J3:J19, "*CASH SALE*", L3:L19, ">="&EOMONTH(TODAY(),-1)+1, L3:L19, "<="&EOMONTH(TODAY(),0)) -> 126575.9 | I23: Cash Sale (June): | J23: =SUMIFS(G3:G19, J3:J19, "*CASH SALE*", L3:L19, ">="&EOMONTH(TODAY(),0)+1, L3:L19, "<="&EOMONTH(TODAY(),1)) -> 0
F24: Account (May): | G24: =SUMIFS(G3:G19, J3:J19, "*ACCOUNT*", L3:L19, ">="&EOMONTH(TODAY(),-1)+1, L3:L19, "<="&EOMONTH(TODAY(),0)) -> 594004.56 | I24: Account (June): | J24: =SUMIFS(G3:G19, J3:J19, "*ACCOUNT*", L3:L19, ">="&EOMONTH(TODAY(),0)+1, L3:L19, "<="&EOMONTH(TODAY(),1)) -> 0
A27: Date | B27: Delivery Date | C27: Job Number | D27: SO Number | E27: Customer Ref. | F27: Customer | G27: Total | H27: Sales Rep | I27: Status | J27: Payment Status | K27: Comments
A28: 46136 | B28: 46149.522 | C28: FM4017 | D28: SO4546 | E28: PO145956 | F28: Howden Power a Div of Howden Africa (Pty) LTD | G28: 15437.6 | H28: Sizwe Tshabalala | I28: In Progress | J28: ACCOUNT - UP TO DATE
A29: 46142 | B29: 46171 | C29: Pending | D29: SO4556 | E29: Constitutional Hill | F29: LJ Trading & Projects (Pty) Ltd | G29: 554227.55 | H29: Simon Mokgola | I29: Pending
A30: 46142 | B30: 46149.522 | C30: FM4031 | D30: SO4565 | E30: POAM26058144 | F30: Allbro Industries (PTY) Ltd | G30: 19154.4 | H30: Sizwe Tshabalala | I30: In Progress | J30: CASH SALE - PAID
A31: 46146 | B31: 46149.522 | C31: FM4025 | D31: SO4559 | E31: PO0000475 | F31: Compu Cool (Pty) Ltd | G31: 11429.61 | H31: Mashudu Tshifularo | I31: In Progress | J31: ACCOUNT - UP TO DATE
F32: Due Today - Total: | G32: =SUM(G28:G31) -> 600249.16
F34: Ready-Dispatch: | G34: =SUMIFS(G3:G19, I3:I19, "*Ready*Dispatch*") -> 0
A37: Recommended Print Range: A1:L39
A38: Suggested Date for Next Update: 08.05.2026

Sheet 08.05.2026
A1: SALES ORDER REPORT | K1: =TODAY() -> 46171
A2: Date | B2: Delivery Date | C2: Job Number | D2: SO Number | E2: Customer Ref. | F2: Customer | G2: Total | H2: Sales Rep | I2: Status | J2: Payment Status | K2: Details | L2: Planned Delivery Date
A3: 46142 | B3: 46155 | C3: FM4031 | D3: SO4565 | E3: POAM26058144 | F3: Allbro Industries (PTY) Ltd | G3: 19154.4 | H3: Sizwe Tshabalala | I3: In Progress | J3: CASH SALE - PAID | K3: HV 7 c/w 0.45kw 6P 380v (Qty: 2), WEATHER LOUVRE 800(W)*800(H) HS NA (Qty: 2) | L3: =B3 -> 46155
A4: 46149 | B4: 46163 | C4: FM4039 | D4: SO4571 | E4: Cash Sale | F4: Shonisani Rambau Construction | G4: 24910.15 | H4: Sizwe Tshabalala | I4: In Progress | J4: CASH SALE - PAID | K4: c/w 1.5 kW 6 Pole 380 V Motor w/ Bird Screen (Qty: 1) | L4: =B4 -> 46163
A5: 46077 | B5: 46169 | C5: FM3874 | D5: SO4404 | E5: PO2174 | F5: ITD North Pty Ltd | G5: 94247.1 | H5: Mashudu Tshifularo | I5: In Progress | J5: CASH SALE – PARTIAL | K5: RDH 710 K2 - Nicotra Fan (Qty: 1) | L5: =B5 -> 46169
A6: 46069 | B6: 46170 | C6: FM3841 | D6: SO4372 | E6: PO2213 | F6: Hucra Fans | G6: 379993.35 | H6: Sales Agent Hucra Fans | I6: In Progress | J6: ACCOUNT - UP TO DATE | K6: SCL K11 MS - 11.0kW - 525V (Qty: 3) | L6: =B6 -> 46170
A7: 46112 | B7: 46170 | C7: FM3974 | D7: SO4502 | E7: 210719 | F7: Kenmare Moma Processing (Mauritius) Limited | G7: 103711 | H7: Sizwe Tshabalala | I7: In Progress | J7: ACCOUNT - UP TO DATE | K7: SCL-K10 MS-11kW - Item no 28000234 (Qty: 1) | L7: =B7 -> 46170
A8: 46112 | B8: 46170 | C8: FM3997 | D8: SO4525 | E8: 211035 | F8: Kenmare Moma Processing (Mauritius) Limited | G8: 83433 | H8: Sizwe Tshabalala | I8: In Progress | J8: ACCOUNT - UP TO DATE | K8: SCL-K08 MS-7.5kW (Qty: 1) | L8: =B8 -> 46170
A9: 46057 | B9: 46171 | C9: Pending | D9: SO4558 | E9: FMTA4398-Thabakgolo | F9: Oribi Air CC | G9: 427841.4 | H9: Mashudu Tshifularo | I9: Pending | K9: LINEO 250 QUIET-5.1.1 (Qty: 24), LINEO 315 QUIET-5.6.1 (Qty: 12) | L9: =B9 -> 46171
A10: 46111 | B10: 46171 | C10: FM3967 | D10: SO4492 | E10: PO260306 | F10: Alpha Air Ventilation Services | G10: 9014.21 | H10: Sizwe Tshabalala | I10: Pending | K10: MAJAX-2 500 c/w 0,55KW 4P 380V (Qty: 1), 500 Diam Counter Flange (Qty: 2) | L10: =B10 -> 46171
A11: 46111 | B11: 46171 | C11: FM3990 | D11: SO4517 | E11: PO:0000426 | F11: Compu Cool (Pty) Ltd | G11: 169353.6 | H11: Mashudu Tshifularo | I11: Pending | K11: UV710/3/6 (Qty: 6) | L11: =B11 -> 46171
A12: 46128 | B12: 46171 | C12: Pending | D12: SO4554 | E12: FMTA4599 | F12: Matla Solution Group | G12: 82900.05 | H12: Mashudu Tshifularo | I12: Pending | K12: LINEO 315 QUIET - EF 1 (Qty: 1), LINEO 250 QUIET - EF 2 (Qty: 1), LINEO 200 QUIET - EF 3 (Qty: 1), KDAXIS 200 - EF 4 (Qty: 1), KDAXIS 200 - EF 5 (Qty: 1), MAXFLO 630/250/14 A c/w 1,10KW 4P 380V - FA 1 (Qty: 1), 630 Diam Silencer 1.5D Podded (Qty: 2), 630 Diam Counter Flange (Qty: 2), 630 Diam Mounting Feet (Qty: 4), 630 to 1000 NDB GREEN Neoprene Floor Mounts (Qty: 8), MAXFLO 710/250/14 A c/w 1,10KW 4P 380V - FA 2 (Qty: 1), 710 Diam Silencer 1.5D Podded (Qty: 2), 710 Diam Counter Flange (Qty: 2), 710 Diam Mounting Feet (Qty: 4), 630 to 1000 NDB GREEN Neoprene Floor Mounts (Qty: 8) | L12: =B12 -> 46171
A13: 46142 | B13: 46171 | C13: Pending | D13: SO4556 | E13: Constitutional Hill | F13: LJ Trading & Projects (Pty) Ltd | G13: 554227.55 | H13: Simon Mokgola | I13: Pending | K13: Constitutional Hill (Qty: 1) | L13: =B13 -> 46171
A14: 46142 | B14: 46171 | C14: Pending | D14: SO4552 | E14: nan | F14: Neobionomics Services Pty Ltd | G14: 13711.09 | H14: Sizwe Tshabalala | I14: Pending | K14: MAJAX-2 630 c/w 0,75KW 4P 380V (Qty: 1) | L14: =B14 -> 46171
A15: 46142 | B15: 46171 | C15: Pending | D15: SO4553 | E15: FMTA4519 | F15: ST AIR SERVICES AND MAINTENANCE (PTY) LTD | G15: 426010.6 | H15: Simon Mokgola | I15: Pending | K15: Mimosa Mall Office Park (Qty: 1) | L15: =B15 -> 46171
A16: 46142 | B16: 46171 | C16: FM4036 | D16: SO4555 | E16: FM4035-FM4036 | F16: Michmat Projects | G16: 310411 | H16: Mashudu - R.O.A | I16: Pending | K16: MFAJAX-3 1250 c/w 45,00KW 4P 380V (Qty: 3), 1250 Diam Counter Flange (Qty: 6), 1250 Diam Mounting Feet (Qty: 6), 630 to 1000 NDB GREEN Neoprene Floor Mounts (Qty: 12), MAJAX-3 560 c/w 5,50KW 2P 380V (Qty: 2), 560 Diam Counter Flange (Qty: 4), 560 Diam Mounting Feet (Qty: 4), 315 to 560 NDA RED ANeoprene Floor Mounts (Qty: 8) | L16: =B16 -> 46171
A17: 46142 | B17: 46171 | C17: Pending | D17: SO4557 | E17: nan | F17: Vigeta Pty Ltd | G17: 204447 | H17: Simon Mokgola | I17: Pending | K17: 630 Diam Vertical Discharge BASE c/w 2.2kW 4P 380V (Qty: 10) | L17: =B17 -> 46171
F18: Total Value (All): | G18: =SUM(G3:G17) -> 2903365.5
F20: BREAKDOWN
F21: Cash Sale (May): | G21: =SUMIFS(G3:G17, J3:J17, "*CASH SALE*", L3:L17, ">="&EOMONTH(TODAY(),-1)+1, L3:L17, "<="&EOMONTH(TODAY(),0)) -> 138311.65 | I21: Cash Sale (June): | J21: =SUMIFS(G3:G17, J3:J17, "*CASH SALE*", L3:L17, ">="&EOMONTH(TODAY(),0)+1, L3:L17, "<="&EOMONTH(TODAY(),1)) -> 0
F22: Account (May): | G22: =SUMIFS(G3:G17, J3:J17, "*ACCOUNT*", L3:L17, ">="&EOMONTH(TODAY(),-1)+1, L3:L17, "<="&EOMONTH(TODAY(),0)) -> 567137.35 | I22: Account (June): | J22: =SUMIFS(G3:G17, J3:J17, "*ACCOUNT*", L3:L17, ">="&EOMONTH(TODAY(),0)+1, L3:L17, "<="&EOMONTH(TODAY(),1)) -> 0
A25: Date | B25: Delivery Date | C25: Job Number | D25: SO Number | E25: Customer Ref. | F25: Customer | G25: Total | H25: Sales Rep | I25: Status | J25: Payment Status | K25: Comments
F27: Due Today - Total: | G27: =SUM(G26:G26) -> 0
F29: Ready-Dispatch: | G29: =SUMIFS(G3:G17, I3:I17, "*Ready*Dispatch*") -> 0

Sheet 11.05.2026
A1: SALES ORDER REPORT | K1: =TODAY() -> 46171
A2: Date | B2: Delivery Date | C2: Job Number | D2: SO Number | E2: Customer Ref. | F2: Customer | G2: Total | H2: Sales Rep | I2: Status | J2: Payment Status | K2: Details | L2: Planned Delivery Date
A3: 46150 | B3: 46153.314 | C3: FM4041 | D3: SO4573 | E3: FM4041 | F3: Airetronic Maintenance & Sales (Pty) Ltd | G3: 8809 | H3: Simon Mokgola | I3: Ready-Dispatch | J3: ACCOUNT - UP TO DATE | K3: NEOLINEO-150/V (Qty: 3), Delivery to Durban (Qty: 1) | L3: =B3 -> 46153.314
A4: 46142 | B4: 46155 | C4: FM4031 | D4: SO4565 | E4: POAM26058144 | F4: Allbro Industries (PTY) Ltd | G4: 19154.4 | H4: Sizwe Tshabalala | I4: In Progress | J4: CASH SALE - PAID | K4: HV 7 c/w 0.45kw 6P 380v (Qty: 2), WEATHER LOUVRE 800(W)*800(H) HS NA (Qty: 2) | L4: =B4 -> 46155
A5: 46149 | B5: 46163 | C5: FM4039 | D5: SO4571 | E5: Cash Sale | F5: Shonisani Rambau Construction | G5: 24910.15 | H5: Sizwe Tshabalala | I5: In Progress | J5: CASH SALE - PAID | K5: UV c/w 1.5 kW 6 Pole 380 V Motor w/ Bird Screen (Qty: 1) | L5: =B5 -> 46163
A6: 46077 | B6: 46169 | C6: FM3874 | D6: SO4404 | E6: PO2174 | F6: ITD North Pty Ltd | G6: 94247.1 | H6: Mashudu Tshifularo | I6: In Progress | J6: CASH SALE – PARTIAL | K6: RDH 710 K2 - Nicotra Fan (Qty: 1) | L6: =B6 -> 46169
A7: 46069 | B7: 46170 | C7: FM3841 | D7: SO4372 | E7: PO2213 | F7: Hucra Fans | G7: 379993.35 | H7: Sales Agent Hucra Fans | I7: In Progress | J7: ACCOUNT - UP TO DATE | K7: SCL K11 MS - 11.0kW - 525V (Qty: 3) | L7: =B7 -> 46170
A8: 46112 | B8: 46170 | C8: FM3974 | D8: SO4502 | E8: 210719 | F8: Kenmare Moma Processing (Mauritius) Limited | G8: 103711 | H8: Sizwe Tshabalala | I8: In Progress | J8: ACCOUNT - UP TO DATE | K8: SCL-K10 MS-11kW - Item no 28000234 (Qty: 1) | L8: =B8 -> 46170
A9: 46112 | B9: 46170 | C9: FM3997 | D9: SO4525 | E9: 211035 | F9: Kenmare Moma Processing (Mauritius) Limited | G9: 83433 | H9: Sizwe Tshabalala | I9: In Progress | J9: ACCOUNT - UP TO DATE | K9: SCL-K08 MS-7.5kW (Qty: 1) | L9: =B9 -> 46170
A10: 46111 | B10: 46171 | C10: FM3967 | D10: SO4492 | E10: PO260306 | F10: Alpha Air Ventilation Services | G10: 9014.21 | H10: Sizwe Tshabalala | I10: On Hold | K10: MAJAX-2 500 c/w 0,55KW 4P 380V (Qty: 1), 500 Diam Counter Flange (Qty: 2) | L10: =B10 -> 46171
A11: 46111 | B11: 46171 | C11: FM3990 | D11: SO4517 | E11: PO:0000426 | F11: Compu Cool (Pty) Ltd | G11: 169353.6 | H11: Mashudu Tshifularo | I11: On Hold | J11: ACCOUNT - UP TO DATE | K11: UV710/3/6 (Qty: 6) | L11: =B11 -> 46171
A12: 46057 | B12: 46171 | C12: Pending | D12: SO4558 | E12: FMTA4398-Thabakgolo | F12: Oribi Air CC | G12: 427841.4 | H12: Mashudu Tshifularo | I12: Pending | K12: LINEO 250 QUIET-5.1.1 (Qty: 24), LINEO 315 QUIET-5.6.1 (Qty: 12) | L12: =B12 -> 46171
A13: 46128 | B13: 46171 | C13: Pending | D13: SO4554 | E13: FMTA4599 | F13: Matla Solution Group | G13: 82900.05 | H13: Mashudu Tshifularo | I13: Pending | K13: LINEO 315 QUIET - EF 1 (Qty: 1), LINEO 250 QUIET - EF 2 (Qty: 1), LINEO 200 QUIET - EF 3 (Qty: 1), KDAXIS 200 - EF 4 (Qty: 1), KDAXIS 200 - EF 5 (Qty: 1), MAXFLO 630/250/14 A c/w 1,10KW 4P 380V - FA 1 (Qty: 1), 630 Diam Silencer 1.5D Podded (Qty: 2), 630 Diam Counter Flange (Qty: 2), 630 Diam Mounting Feet (Qty: 4), 630 to 1000 NDB GREEN Neoprene Floor Mounts (Qty: 8), MAXFLO 710/250/14 A c/w 1,10KW 4P 380V - FA 2 (Qty: 1), 710 Diam Silencer 1.5D Podded (Qty: 2), 710 Diam Counter Flange (Qty: 2), 710 Diam Mounting Feet (Qty: 4), 630 to 1000 NDB GREEN Neoprene Floor Mounts (Qty: 8) | L13: =B13 -> 46171
A14: 46142 | B14: 46171 | C14: Pending | D14: SO4556 | E14: Constitutional Hill | F14: LJ Trading & Projects (Pty) Ltd | G14: 554227.55 | H14: Simon Mokgola | I14: Pending | K14: Constitutional Hill (Qty: 1) | L14: =B14 -> 46171
A15: 46142 | B15: 46171 | C15: Pending | D15: SO4552 | E15: nan | F15: Neobionomics Services Pty Ltd | G15: 13711.09 | H15: Sizwe Tshabalala | I15: Pending | K15: MAJAX-2 630 c/w 0,75KW 4P 380V (Qty: 1) | L15: =B15 -> 46171
A16: 46142 | B16: 46171 | C16: Pending | D16: SO4553 | E16: FMTA4519 | F16: ST AIR SERVICES AND MAINTENANCE (PTY) LTD | G16: 426010.6 | H16: Simon Mokgola | I16: Pending | K16: Mimosa Mall Office Park (Qty: 1) | L16: =B16 -> 46171
A17: 46142 | B17: 46171 | C17: FM4036 | D17: SO4555 | E17: FM4035-FM4036 | F17: Michmat Projects | G17: 310411 | H17: Mashudu - R.O.A | I17: Pending | K17: MFAJAX-3 1250 c/w 45,00KW 4P 380V (Qty: 3), 1250 Diam Counter Flange (Qty: 6), 1250 Diam Mounting Feet (Qty: 6), 630 to 1000 NDB GREEN Neoprene Floor Mounts (Qty: 12), MAJAX-3 560 c/w 5,50KW 2P 380V (Qty: 2), 560 Diam Counter Flange (Qty: 4), 560 Diam Mounting Feet (Qty: 4), 315 to 560 NDA RED ANeoprene Floor Mounts (Qty: 8) | L17: =B17 -> 46171
A18: 46142 | B18: 46171 | C18: Pending | D18: SO4557 | E18: nan | F18: Vigeta Pty Ltd | G18: 204447 | H18: Simon Mokgola | I18: Pending | K18: 630 Diam Vertical Discharge BASE c/w 2.2kW 4P 380V (Qty: 10) | L18: =B18 -> 46171
F19: Total Value (All): | G19: =SUM(G3:G18) -> 2912174.5
F21: BREAKDOWN
F22: Cash Sale (May): | G22: =SUMIFS(G3:G18, J3:J18, "*CASH SALE*", L3:L18, ">="&EOMONTH(TODAY(),-1)+1, L3:L18, "<="&EOMONTH(TODAY(),0)) -> 138311.65 | I22: Cash Sale (June): | J22: =SUMIFS(G3:G18, J3:J18, "*CASH SALE*", L3:L18, ">="&EOMONTH(TODAY(),0)+1, L3:L18, "<="&EOMONTH(TODAY(),1)) -> 0
F23: Account (May): | G23: =SUMIFS(G3:G18, J3:J18, "*ACCOUNT*", L3:L18, ">="&EOMONTH(TODAY(),-1)+1, L3:L18, "<="&EOMONTH(TODAY(),0)) -> 745299.95 | I23: Account (June): | J23: =SUMIFS(G3:G18, J3:J18, "*ACCOUNT*", L3:L18, ">="&EOMONTH(TODAY(),0)+1, L3:L18, "<="&EOMONTH(TODAY(),1)) -> 0
A25: Date | B25: Delivery Date | C25: Job Number | D25: SO Number | E25: Customer Ref. | F25: Customer | G25: Total | H25: Sales Rep | I25: Status | J25: Payment Status | K25: Comments
A26: 46150 | B26: 46153.314 | C26: FM4041 | D26: SO4573 | E26: FM4041 | F26: Airetronic Maintenance & Sales (Pty) Ltd | G26: 8809 | H26: Simon Mokgola | I26: In Progress | J26: ACCOUNT - UP TO DATE | K26: Delivery via Courier 11/05/2026
F27: Due Today - Total: | G27: =SUM(G26:G26) -> 8809
F29: Ready-Dispatch: | G29: =SUMIFS(G3:G18, I3:I18, "*Ready*Dispatch*") -> 8809

Sheet 12.05.2026
A1: SALES ORDER REPORT | K1: =TODAY() -> 46171
A2: Date | B2: Delivery Date | C2: Job Number | D2: SO Number | E2: Customer Ref. | F2: Customer | G2: Total | H2: Sales Rep | I2: Status | J2: Payment Status | K2: Details | L2: Planned Delivery Date
A3: 46142 | B3: 46154.349 | C3: Pending | D3: SO4556 | E3: Constitutional Hill | F3: LJ Trading & Projects (Pty) Ltd | G3: 554227.55 | H3: Simon Mokgola | I3: Pending | J3: =IFERROR(VLOOKUP(D3, '11.05.2026'!D:J, 7, FALSE), "") -> 0 | K3: Constitutional Hill (Qty: 1) | L3: =B3 -> 46154.349
A4: 46142 | B4: 46154.349 | C4: FM4031 | D4: SO4565 | E4: POAM26058144 | F4: Allbro Industries (PTY) Ltd | G4: 19154.4 | H4: Sizwe Tshabalala | I4: In Progress | J4: CASH SALE - PAID | K4: HV 7 c/w 0.45kw 6P 380v (Qty: 2), WEATHER LOUVRE 800(W)*800(H) HS NA (Qty: 2) | L4: =B4 -> 46154.349
A5: 46153 | B5: 46154.349 | C5: FM4043 | D5: SO4575 | E5: SAMPLE - BLOCK A | F5: Luft Technik (Pty) Ltd | G5: 0 | H5: Mashudu Tshifularo | I5: In Progress | J5: ACCOUNT - UP TO DATE | K5: MAXFLO 315/150/10 A c/w 0.37kW 2P 380V (Qty: 1) | L5: =B5 -> 46154.349
A6: 46153 | B6: 46154.349 | C6: FM4044 | D6: SO4576 | E6: FM4044 | F6: Systemair (Pty) Ltd | G6: 16067.8 | H6: Mashudu Tshifularo | I6: In Progress | J6: CASH SALE - PAID | K6: Tiracamino Chimney Fan for Chimney Tops (Qty: 1) | L6: =B6 -> 46154.349
A7: 46149 | B7: 46163 | C7: FM4039 | D7: SO4571 | E7: Cash Sale | F7: Shonisani Rambau Construction | G7: 24910.15 | H7: Sizwe Tshabalala | I7: In Progress | J7: CASH SALE - PAID | K7: c/w 1.5 kW 6 Pole 380 V Motor w/ Bird Screen (Qty: 1) | L7: =B7 -> 46163
A8: 46077 | B8: 46169 | C8: FM3874 | D8: SO4404 | E8: PO2174 | F8: ITD North Pty Ltd | G8: 94247.1 | H8: Mashudu Tshifularo | I8: In Progress | J8: CASH SALE – PARTIAL | K8: RDH 710 K2 - Nicotra Fan (Qty: 1) | L8: =B8 -> 46169
A9: 46069 | B9: 46170 | C9: FM3841 | D9: SO4372 | E9: PO2213 | F9: Hucra Fans | G9: 379993.35 | H9: Sales Agent Hucra Fans | I9: In Progress | J9: ACCOUNT - UP TO DATE | K9: SCL K11 MS - 11.0kW - 525V (Qty: 3) | L9: =B9 -> 46170
A10: 46112 | B10: 46170 | C10: FM3974 | D10: SO4502 | E10: 210719 | F10: Kenmare Moma Processing (Mauritius) Limited | G10: 103711 | H10: Sizwe Tshabalala | I10: In Progress | J10: ACCOUNT - UP TO DATE | K10: SCL-K10 MS-11kW - Item no 28000234 (Qty: 1) | L10: =B10 -> 46170
A11: 46112 | B11: 46170 | C11: FM3997 | D11: SO4525 | E11: 211035 | F11: Kenmare Moma Processing (Mauritius) Limited | G11: 83433 | H11: Sizwe Tshabalala | I11: In Progress | J11: ACCOUNT - UP TO DATE | K11: SCL-K08 MS-7.5kW (Qty: 1) | L11: =B11 -> 46170
A12: 46057 | B12: 46171 | C12: Pending | D12: SO4558 | E12: FMTA4398-Thabakgolo | F12: Oribi Air CC | G12: 427841.4 | H12: Mashudu Tshifularo | I12: Pending | J12: =IFERROR(VLOOKUP(D12, '11.05.2026'!D:J, 7, FALSE), "") -> 0 | K12: LINEO 250 QUIET-5.1.1 (Qty: 24), LINEO 315 QUIET-5.6.1 (Qty: 12) | L12: =B12 -> 46171
A13: 46111 | B13: 46171 | C13: FM3967 | D13: SO4492 | E13: PO260306 | F13: Alpha Air Ventilation Services | G13: 9014.21 | H13: Sizwe Tshabalala | I13: On Hold | J13: =IFERROR(VLOOKUP(D13, '11.05.2026'!D:J, 7, FALSE), "") -> 0 | K13: MAJAX-2 500 c/w 0,55KW 4P 380V (Qty: 1), 500 Diam Counter Flange (Qty: 2) | L13: =B13 -> 46171
A14: 46111 | B14: 46171 | C14: FM3990 | D14: SO4517 | E14: PO:0000426 | F14: Compu Cool (Pty) Ltd | G14: 169353.6 | H14: Mashudu Tshifularo | I14: On Hold | J14: =IFERROR(VLOOKUP(D14, '11.05.2026'!D:J, 7, FALSE), "") -> ACCOUNT - UP TO DATE | K14: UV710/3/6 (Qty: 6) | L14: =B14 -> 46171
A15: 46128 | B15: 46171 | C15: Pending | D15: SO4554 | E15: FMTA4599 | F15: Matla Solution Group | G15: 82900.05 | H15: Mashudu Tshifularo | I15: Pending | J15: =IFERROR(VLOOKUP(D15, '11.05.2026'!D:J, 7, FALSE), "") -> 0 | K15: LINEO 315 QUIET - EF 1 (Qty: 1), LINEO 250 QUIET - EF 2 (Qty: 1), LINEO 200 QUIET - EF 3 (Qty: 1), KDAXIS 200 - EF 4 (Qty: 1), KDAXIS 200 - EF 5 (Qty: 1), MAXFLO 630/250/14 A c/w 1,10KW 4P 380V - FA 1 (Qty: 1), 630 Diam Silencer 1.5D Podded (Qty: 2), 630 Diam Counter Flange (Qty: 2), 630 Diam Mounting Feet (Qty: 4), 630 to 1000 NDB GREEN Neoprene Floor Mounts (Qty: 8), MAXFLO 710/250/14 A c/w 1,10KW 4P 380V - FA 2 (Qty: 1), 710 Diam Silencer 1.5D Podded (Qty: 2), 710 Diam Counter Flange (Qty: 2), 710 Diam Mounting Feet (Qty: 4), 630 to 1000 NDB GREEN Neoprene Floor Mounts (Qty: 8) | L15: =B15 -> 46171
A16: 46142 | B16: 46171 | C16: Pending | D16: SO4552 | E16: nan | F16: Neobionomics Services Pty Ltd | G16: 13711.09 | H16: Sizwe Tshabalala | I16: Pending | J16: =IFERROR(VLOOKUP(D16, '11.05.2026'!D:J, 7, FALSE), "") -> 0 | K16: MAJAX-2 630 c/w 0,75KW 4P 380V (Qty: 1) | L16: =B16 -> 46171
A17: 46142 | B17: 46171 | C17: Pending | D17: SO4553 | E17: FMTA4519 | F17: ST AIR SERVICES AND MAINTENANCE (PTY) LTD | G17: 426010.6 | H17: Simon Mokgola | I17: Pending | J17: =IFERROR(VLOOKUP(D17, '11.05.2026'!D:J, 7, FALSE), "") -> 0 | K17: Mimosa Mall Office Park (Qty: 1) | L17: =B17 -> 46171
A18: 46142 | B18: 46171 | C18: FM4036 | D18: SO4555 | E18: FM4035-FM4036 | F18: Michmat Projects | G18: 310411 | H18: Mashudu - R.O.A | I18: Pending | J18: =IFERROR(VLOOKUP(D18, '11.05.2026'!D:J, 7, FALSE), "") -> 0 | K18: MFAJAX-3 1250 c/w 45,00KW 4P 380V (Qty: 3), 1250 Diam Counter Flange (Qty: 6), 1250 Diam Mounting Feet (Qty: 6), 630 to 1000 NDB GREEN Neoprene Floor Mounts (Qty: 12), MAJAX-3 560 c/w 5,50KW 2P 380V (Qty: 2), 560 Diam Counter Flange (Qty: 4), 560 Diam Mounting Feet (Qty: 4), 315 to 560 NDA RED ANeoprene Floor Mounts (Qty: 8) | L18: =B18 -> 46171
A19: 46142 | B19: 46171 | C19: Pending | D19: SO4557 | E19: nan | F19: Vigeta Pty Ltd | G19: 204447 | H19: Simon Mokgola | I19: Pending | J19: =IFERROR(VLOOKUP(D19, '11.05.2026'!D:J, 7, FALSE), "") -> 0 | K19: 630 Diam Vertical Discharge BASE c/w 2.2kW 4P 380V (Qty: 10) | L19: =B19 -> 46171
A20: 46154 | B20: 46173 | C20: FM4055 | D20: SO4577 | E20: FM4055 | F20: Vincent | G20: 12224.5 | H20: Simon Mokgola | I20: Pending | J20: =IFERROR(VLOOKUP(D20, '11.05.2026'!D:J, 7, FALSE), "") | K20: MAJAX-3 500 (BIFUCATED) c/w 0.55KW 4P 380V (Qty: 1) | L20: =B20 -> 46173
A21: 46154 | B21: 46173 | C21: FM4056 | D21: SO4578 | E21: FM4056 | F21: ADC Engineers | G21: 4322.85 | H21: Simon Mokgola | I21: Pending | J21: =IFERROR(VLOOKUP(D21, '11.05.2026'!D:J, 7, FALSE), "") | K21: RAD 150 (Qty: 1), RAD 250 (Qty: 1) | L21: =B21 -> 46173
F22: Total Value (All): | G22: =SUM(G3:G21) -> 2935980.7
F24: BREAKDOWN
F25: Cash Sale (May): | G25: =SUMIFS(G3:G21, J3:J21, "*CASH SALE*", L3:L21, ">="&EOMONTH(TODAY(),-1)+1, L3:L21, "<="&EOMONTH(TODAY(),0)) -> 154379.45 | I25: Cash Sale (June): | J25: =SUMIFS(G3:G21, J3:J21, "*CASH SALE*", L3:L21, ">="&EOMONTH(TODAY(),0)+1, L3:L21, "<="&EOMONTH(TODAY(),1)) -> 0
F26: Account (May): | G26: =SUMIFS(G3:G21, J3:J21, "*ACCOUNT*", L3:L21, ">="&EOMONTH(TODAY(),-1)+1, L3:L21, "<="&EOMONTH(TODAY(),0)) -> 736490.95 | I26: Account (June): | J26: =SUMIFS(G3:G21, J3:J21, "*ACCOUNT*", L3:L21, ">="&EOMONTH(TODAY(),0)+1, L3:L21, "<="&EOMONTH(TODAY(),1)) -> 0
A29: Date | B29: Delivery Date | C29: Job Number | D29: SO Number | E29: Customer Ref. | F29: Customer | G29: Total | H29: Sales Rep | I29: Status | J29: Payment Status | K29: Comments
A30: 46142 | B30: 46154.349 | C30: Pending | D30: SO4556 | E30: Constitutional Hill | F30: LJ Trading & Projects (Pty) Ltd | G30: 554227.55 | H30: Simon Mokgola | I30: Pending
A31: 46142 | B31: 46154.349 | C31: FM4031 | D31: SO4565 | E31: POAM26058144 | F31: Allbro Industries (PTY) Ltd | G31: 19154.4 | H31: Sizwe Tshabalala | I31: In Progress | J31: CASH SALE - PAID
A32: 46153 | B32: 46154.349 | C32: FM4043 | D32: SO4575 | E32: SAMPLE - BLOCK A | F32: Luft Technik (Pty) Ltd | G32: 0 | H32: Mashudu Tshifularo | I32: In Progress | J32: ACCOUNT - UP TO DATE
A33: 46153 | B33: 46154.349 | C33: FM4044 | D33: SO4576 | E33: FM4044 | F33: Systemair (Pty) Ltd | G33: 16067.8 | H33: Mashudu Tshifularo | I33: In Progress | J33: CASH SALE - PAID
F34: Due Today - Total: | G34: =SUM(G30:G33) -> 589449.75
F36: Ready-Dispatch: | G36: =SUMIFS(G3:G21, I3:I21, "*Ready*Dispatch*") -> 0
A39: Recommended Print Range: A1:L41
A40: Suggested Date for Next Update: 13.05.2026

Sheet 13.05.2026
A1: SALES ORDER REPORT | K1: =TODAY() -> 46171
A2: Date | B2: Delivery Date | C2: Job Number | D2: SO Number | E2: Customer Ref. | F2: Customer | G2: Total | H2: Sales Rep | I2: Status | J2: Payment Status | K2: Details | L2: Planned Delivery Date
A3: 46154 | B3: 46155.363 | C3: FM4026 | D3: SO4582 | E3: cash sale | F3: Carrons Corporate Maintenance | G3: 15092.97 | H3: Mashudu Tshifularo | I3: Ready - Dispatch | J3: CASH SALE - PAID | K3: V 300/12 AR (Qty: 2), Door grill 300mm x 300mm neck size (Qty: 3) | L3: =B3 -> 46155.363
A4: 46154 | B4: 46155.363 | C4: FM4060 | D4: SO4580 | E4: FM4060 | F4: Roto Tank | G4: 10263.75 | H4: Sizwe Tshabalala | I4: Ready - Dispatch | J4: CASH SALE - PAID | K4: CMP 616 2M (Qty: 1) | L4: =B4 -> 46155.363
A5: 46154 | B5: 46156 | C5: FM4059 | D5: SO4579 | E5: FM4057 | F5: Aircontech Technologies | G5: 50610.35 | H5: Simon Mokgola | I5: In Progress | J5: ACCOUNT - UP TO DATE | K5: MAXFLO 630/250/14 A c/w 0,75KW 4P 380V - EAF 04 (Qty: 1), 630 Diam Silencer 1.5D Podded (Qty: 2), 630 Diam Counter Flange (Qty: 2), 630 Diam Mounting Feet (Qty: 4), 630 to 1000 NDB GREEN Neoprene Floor Mounts (Qty: 8), CA/LINE-20 - EAF 01 (Qty: 1), 200 Diam Tube Silencer 600L (Qty: 2), CA/LINE-25 - EAF 02 (Qty: 1), 250 Diam Tube Silencer 600L (Qty: 2), MAXFLO 315/150/10 A c/w 0,55KW 2P 380V - EAF 03 (Qty: 1), 315 Diam Silencer 1.5D Podded (Qty: 2), 315 Diam Counter Flange (Qty: 2), 315 Diam Mounting Feet (Qty: 4), 315 to 560 NDA RED ANeoprene Floor Mounts (Qty: 8), KDAXIS 250 - WMF 01 (Qty: 1), KDAXIS 250 - WMF 02 (Qty: 1), KDAXIS 250 - WMF 03 (Qty: 1), KDAXIS 250 - WMF 04 (Qty: 1) | L5: =B5 -> 46156
A6: 46149 | B6: 46163 | C6: FM4039 | D6: SO4571 | E6: Cash Sale | F6: Shonisani Rambau Construction | G6: 24910.15 | H6: Sizwe Tshabalala | I6: In Progress | J6: CASH SALE - PAID | K6: UV c/w 1.5 kW 6 Pole 380 V Motor w/ Bird Screen (Qty: 1) | L6: =B6 -> 46163
A7: 46154 | B7: 46164 | C7: FM4055 | D7: SO4577 | E7: FM4055 | F7: Vincent | G7: 12224.5 | H7: Simon Mokgola | I7: In Progress | J7: CASH SALE - PAID | K7: MAJAX-3 500 (BIFUCATED) c/w 0.55KW 4P 380V (Qty: 1) | L7: =B7 -> 46164
A8: 46077 | B8: 46169 | C8: FM3874 | D8: SO4404 | E8: PO2174 | F8: ITD North Pty Ltd | G8: 94247.1 | H8: Mashudu Tshifularo | I8: In Progress | J8: CASH SALE – PARTIAL | K8: RDH 710 K2 - Nicotra Fan (Qty: 1) | L8: =B8 -> 46169
A9: 46069 | B9: 46170 | C9: FM3841 | D9: SO4372 | E9: PO2213 | F9: Hucra Fans | G9: 379993.35 | H9: Sales Agent Hucra Fans | I9: In Progress | J9: ACCOUNT - UP TO DATE | K9: SCL K11 MS - 11.0kW - 525V (Qty: 3) | L9: =B9 -> 46170
A10: 46112 | B10: 46170 | C10: FM3974 | D10: SO4502 | E10: 210719 | F10: Kenmare Moma Processing (Mauritius) Limited | G10: 103711 | H10: Sizwe Tshabalala | I10: In Progress | J10: ACCOUNT - UP TO DATE | K10: SCL-K10 MS-11kW - Item no 28000234 (Qty: 1) | L10: =B10 -> 46170
A11: 46112 | B11: 46170 | C11: FM3997 | D11: SO4525 | E11: 211035 | F11: Kenmare Moma Processing (Mauritius) Limited | G11: 83433 | H11: Sizwe Tshabalala | I11: In Progress | J11: ACCOUNT - UP TO DATE | K11: SCL-K08 MS-7.5kW (Qty: 1) | L11: =B11 -> 46170
A12: 46111 | B12: 46171 | C12: FM3967 | D12: SO4492 | E12: PO260306 | F12: Alpha Air Ventilation Services | G12: 9014.21 | H12: Sizwe Tshabalala | I12: On Hold | K12: MAJAX-2 500 c/w 0,55KW 4P 380V (Qty: 1), 500 Diam Counter Flange (Qty: 2) | L12: =B12 -> 46171
A13: 46111 | B13: 46171 | C13: FM3990 | D13: SO4517 | E13: PO:0000426 | F13: Compu Cool (Pty) Ltd | G13: 169353.6 | H13: Mashudu Tshifularo | I13: On Hold | J13: =IFERROR(VLOOKUP(D13, '12.05.2026'!D:J, 7, FALSE), "") -> ACCOUNT - UP TO DATE | K13: UV710/3/6 (Qty: 6) | L13: =B13 -> 46171
A14: 46142 | B14: 46171 | C14: FM4036 | D14: SO4555 | E14: FM4035-FM4036 | F14: Michmat Projects | G14: 310411 | H14: Mashudu - R.O.A | I14: Pending | K14: MFAJAX-3 1250 c/w 45,00KW 4P 380V (Qty: 3), 1250 Diam Counter Flange (Qty: 6), 1250 Diam Mounting Feet (Qty: 6), 630 to 1000 NDB GREEN Neoprene Floor Mounts (Qty: 12), MAJAX-3 560 c/w 5,50KW 2P 380V (Qty: 2), 560 Diam Counter Flange (Qty: 4), 560 Diam Mounting Feet (Qty: 4), 315 to 560 NDA RED ANeoprene Floor Mounts (Qty: 8) | L14: =B14 -> 46171
A15: 46057 | B15: 46171 | C15: Pending | D15: SO4558 | E15: FMTA4398-Thabakgolo | F15: Oribi Air CC | G15: 427841.4 | H15: Mashudu Tshifularo | I15: Pending | K15: LINEO 250 QUIET-5.1.1 (Qty: 24), LINEO 315 QUIET-5.6.1 (Qty: 12) | L15: =B15 -> 46171
A16: 46128 | B16: 46171 | C16: Pending | D16: SO4554 | E16: FMTA4599 | F16: Matla Solution Group | G16: 82900.05 | H16: Mashudu Tshifularo | I16: Pending | K16: LINEO 315 QUIET - EF 1 (Qty: 1), LINEO 250 QUIET - EF 2 (Qty: 1), LINEO 200 QUIET - EF 3 (Qty: 1), KDAXIS 200 - EF 4 (Qty: 1), KDAXIS 200 - EF 5 (Qty: 1), MAXFLO 630/250/14 A c/w 1,10KW 4P 380V - FA 1 (Qty: 1), 630 Diam Silencer 1.5D Podded (Qty: 2), 630 Diam Counter Flange (Qty: 2), 630 Diam Mounting Feet (Qty: 4), 630 to 1000 NDB GREEN Neoprene Floor Mounts (Qty: 8), MAXFLO 710/250/14 A c/w 1,10KW 4P 380V - FA 2 (Qty: 1), 710 Diam Silencer 1.5D Podded (Qty: 2), 710 Diam Counter Flange (Qty: 2), 710 Diam Mounting Feet (Qty: 4), 630 to 1000 NDB GREEN Neoprene Floor Mounts (Qty: 8) | L16: =B16 -> 46171
A17: 46142 | B17: 46171 | C17: Pending | D17: SO4556 | E17: Constitutional Hill | F17: LJ Trading & Projects (Pty) Ltd | G17: 554227.55 | H17: Simon Mokgola | I17: Pending | K17: Constitutional Hill (Qty: 1) | L17: =B17 -> 46171
A18: 46142 | B18: 46171 | C18: Pending | D18: SO4552 | E18: nan | F18: Neobionomics Services Pty Ltd | G18: 13711.09 | H18: Sizwe Tshabalala | I18: Pending | K18: MAJAX-2 630 c/w 0,75KW 4P 380V (Qty: 1) | L18: =B18 -> 46171
A19: 46142 | B19: 46171 | C19: Pending | D19: SO4553 | E19: FMTA4519 | F19: ST AIR SERVICES AND MAINTENANCE (PTY) LTD | G19: 426010.6 | H19: Simon Mokgola | I19: Pending | K19: Mimosa Mall Office Park (Qty: 1) | L19: =B19 -> 46171
A20: 46142 | B20: 46171 | C20: Pending | D20: SO4557 | E20: nan | F20: Vigeta Pty Ltd | G20: 204447 | H20: Simon Mokgola | I20: Pending | K20: 630 Diam Vertical Discharge BASE c/w 2.2kW 4P 380V (Qty: 10) | L20: =B20 -> 46171
A21: 46155 | B21: 46199 | C21: Pending | D21: SO4584 | E21: 211563 | F21: Kenmare Moma Processing (Mauritius) Limited | G21: 523356 | H21: Sizwe - R.O.A | I21: Pending | J21: =IFERROR(VLOOKUP(D21, '12.05.2026'!D:J, 7, FALSE), "") | K21: SCL-K11 TS-22kW - Item No 28000552 (Qty: 2) | L21: =B21 -> 46199
F22: Total Value (All): | G22: =SUM(G3:G21) -> 3495758.7
F24: BREAKDOWN
F25: Cash Sale (May): | G25: =SUMIFS(G3:G21, J3:J21, "*CASH SALE*", L3:L21, ">="&EOMONTH(TODAY(),-1)+1, L3:L21, "<="&EOMONTH(TODAY(),0)) -> 156738.47 | I25: Cash Sale (June): | J25: =SUMIFS(G3:G21, J3:J21, "*CASH SALE*", L3:L21, ">="&EOMONTH(TODAY(),0)+1, L3:L21, "<="&EOMONTH(TODAY(),1)) -> 0
F26: Account (May): | G26: =SUMIFS(G3:G21, J3:J21, "*ACCOUNT*", L3:L21, ">="&EOMONTH(TODAY(),-1)+1, L3:L21, "<="&EOMONTH(TODAY(),0)) -> 787101.3 | I26: Account (June): | J26: =SUMIFS(G3:G21, J3:J21, "*ACCOUNT*", L3:L21, ">="&EOMONTH(TODAY(),0)+1, L3:L21, "<="&EOMONTH(TODAY(),1)) -> 0
A28: Date | B28: Delivery Date | C28: Job Number | D28: SO Number | E28: Customer Ref. | F28: Customer | G28: Total | H28: Sales Rep | I28: Status | J28: Payment Status | K28: Comments
A29: 46154 | B29: 46155.363 | C29: FM4060 | D29: SO4580 | E29: FM4060 | F29: Roto Tank | G29: 10263.75 | H29: Sizwe Tshabalala | I29: Ready - Dispatch | J29: CASH SALE - PAID
A30: 46154 | B30: 46155.363 | C30: FM4026 | D30: SO4582 | E30: cash sale | F30: Carrons Corporate Maintenance | G30: 15092.97 | H30: Mashudu Tshifularo | I30: Ready - Dispatch | J30: CASH SALE - PAID
F31: Due Today - Total: | G31: =SUM(G29:G30) -> 25356.72
F33: Ready-Dispatch: | G33: =SUMIFS(G3:G21, I3:I21, "*Ready*Dispatch*") -> 25356.72

Sheet 14.05.2026
A1: SALES ORDER REPORT | K1: =TODAY() -> 46171
A2: Date | B2: Delivery Date | C2: Job Number | D2: SO Number | E2: Customer Ref. | F2: Customer | G2: Total | H2: Sales Rep | I2: Status | J2: Payment Status | K2: Details | L2: Planned Delivery Date
A3: 46154 | B3: 46156.327 | C3: FM4059 | D3: SO4579 | E3: FM4057 | F3: Aircontech Technologies | G3: 50610.35 | H3: Simon Mokgola | I3: In Progress | J3: ACCOUNT - UP TO DATE | K3: MAXFLO 630/250/14 A c/w 0,75KW 4P 380V - EAF 04 (Qty: 1), 630 Diam Silencer 1.5D Podded (Qty: 2), 630 Diam Counter Flange (Qty: 2), 630 Diam Mounting Feet (Qty: 4), 630 to 1000 NDB GREEN Neoprene Floor Mounts (Qty: 8), CA/LINE-20 - EAF 01 (Qty: 1), 200 Diam Tube Silencer 600L (Qty: 2), CA/LINE-25 - EAF 02 (Qty: 1), 250 Diam Tube Silencer 600L (Qty: 2), MAXFLO 315/150/10 A c/w 0,55KW 2P 380V - EAF 03 (Qty: 1), 315 Diam Silencer 1.5D Podded (Qty: 2), 315 Diam Counter Flange (Qty: 2), 315 Diam Mounting Feet (Qty: 4), 315 to 560 NDA RED ANeoprene Floor Mounts (Qty: 8), KDAXIS 250 - WMF 01 (Qty: 1), KDAXIS 250 - WMF 02 (Qty: 1), KDAXIS 250 - WMF 03 (Qty: 1), KDAXIS 250 - WMF 04 (Qty: 1) | L3: =B3 -> 46156.327
A4: 46154 | B4: 46156.327 | C4: FM4060 | D4: SO4580 | E4: FM4060 | F4: Roto Tank | G4: 10263.75 | H4: Sizwe Tshabalala | I4: Ready - Dispatch | J4: CASH SALE - PAID | K4: CMP 616 2M (Qty: 1) | L4: =B4 -> 46156.327
A5: 46154 | B5: 46161 | C5: FM4055 | D5: SO4577 | E5: FM4055 | F5: Vincent | G5: 12224.5 | H5: Simon Mokgola | I5: In Progress | J5: CASH SALE - PAID | K5: MAJAX-3 500 (BIFUCATED) c/w 0.55KW 4P 380V (Qty: 1) | L5: =B5 -> 46161
A6: 46149 | B6: 46163 | C6: FM4039 | D6: SO4571 | E6: Cash Sale | F6: Shonisani Rambau Construction | G6: 24910.15 | H6: Sizwe Tshabalala | I6: In Progress | J6: CASH SALE - PAID | K6: UV c/w 1.5 kW 6 Pole 380 V Motor w/ Bird Screen (Qty: 1) | L6: =B6 -> 46163
A7: 46077 | B7: 46169 | C7: FM3874 | D7: SO4404 | E7: PO2174 | F7: ITD North Pty Ltd | G7: 94247.1 | H7: Mashudu Tshifularo | I7: In Progress | J7: CASH SALE – PARTIAL | K7: RDH 710 K2 - Nicotra Fan (Qty: 1) | L7: =B7 -> 46169
A8: 46069 | B8: 46170 | C8: FM3841 | D8: SO4372 | E8: PO2213 | F8: Hucra Fans | G8: 379993.35 | H8: Sales Agent Hucra Fans | I8: In Progress | J8: ACCOUNT - UP TO DATE | K8: SCL K11 MS - 11.0kW - 525V (Qty: 3) | L8: =B8 -> 46170
A9: 46112 | B9: 46170 | C9: FM3974 | D9: SO4502 | E9: 210719 | F9: Kenmare Moma Processing (Mauritius) Limited | G9: 103711 | H9: Sizwe Tshabalala | I9: In Progress | J9: ACCOUNT - UP TO DATE | K9: SCL-K10 MS-11kW - Item no 28000234 (Qty: 1) | L9: =B9 -> 46170
A10: 46112 | B10: 46170 | C10: FM3997 | D10: SO4525 | E10: 211035 | F10: Kenmare Moma Processing (Mauritius) Limited | G10: 83433 | H10: Sizwe Tshabalala | I10: In Progress | J10: ACCOUNT - UP TO DATE | K10: SCL-K08 MS-7.5kW (Qty: 1) | L10: =B10 -> 46170
A11: 46111 | B11: 46171 | C11: FM3967 | D11: SO4492 | E11: PO260306 | F11: Alpha Air Ventilation Services | G11: 9014.21 | H11: Sizwe Tshabalala | I11: On Hold | K11: MAJAX-2 500 c/w 0,55KW 4P 380V (Qty: 1), 500 Diam Counter Flange (Qty: 2) | L11: =B11 -> 46171
A12: 46111 | B12: 46171 | C12: FM3990 | D12: SO4517 | E12: PO:0000426 | F12: Compu Cool (Pty) Ltd | G12: 169353.6 | H12: Mashudu Tshifularo | I12: On Hold | J12: =IFERROR(VLOOKUP(D12, '13.05.2026'!D:J, 7, FALSE), "") -> ACCOUNT - UP TO DATE | K12: UV710/3/6 (Qty: 6) | L12: =B12 -> 46171
A13: 46057 | B13: 46171 | C13: Pending | D13: SO4558 | E13: FMTA4398-Thabakgolo | F13: Oribi Air CC | G13: 427841.4 | H13: Mashudu Tshifularo | I13: Pending | K13: LINEO 250 QUIET-5.1.1 (Qty: 24), LINEO 315 QUIET-5.6.1 (Qty: 12) | L13: =B13 -> 46171
A14: 46128 | B14: 46171 | C14: Pending | D14: SO4554 | E14: FMTA4599 | F14: Matla Solution Group | G14: 82900.05 | H14: Mashudu Tshifularo | I14: Pending | K14: LINEO 315 QUIET - EF 1 (Qty: 1), LINEO 250 QUIET - EF 2 (Qty: 1), LINEO 200 QUIET - EF 3 (Qty: 1), KDAXIS 200 - EF 4 (Qty: 1), KDAXIS 200 - EF 5 (Qty: 1), MAXFLO 630/250/14 A c/w 1,10KW 4P 380V - FA 1 (Qty: 1), 630 Diam Silencer 1.5D Podded (Qty: 2), 630 Diam Counter Flange (Qty: 2), 630 Diam Mounting Feet (Qty: 4), 630 to 1000 NDB GREEN Neoprene Floor Mounts (Qty: 8), MAXFLO 710/250/14 A c/w 1,10KW 4P 380V - FA 2 (Qty: 1), 710 Diam Silencer 1.5D Podded (Qty: 2), 710 Diam Counter Flange (Qty: 2), 710 Diam Mounting Feet (Qty: 4), 630 to 1000 NDB GREEN Neoprene Floor Mounts (Qty: 8) | L14: =B14 -> 46171
A15: 46142 | B15: 46171 | C15: Pending | D15: SO4556 | E15: Constitutional Hill | F15: LJ Trading & Projects (Pty) Ltd | G15: 554227.55 | H15: Simon Mokgola | I15: Pending | K15: Constitutional Hill (Qty: 1) | L15: =B15 -> 46171
A16: 46142 | B16: 46171 | C16: Pending | D16: SO4552 | E16: nan | F16: Neobionomics Services Pty Ltd | G16: 13711.09 | H16: Sizwe Tshabalala | I16: Pending | K16: MAJAX-2 630 c/w 0,75KW 4P 380V (Qty: 1) | L16: =B16 -> 46171
A17: 46142 | B17: 46171 | C17: Pending | D17: SO4553 | E17: FMTA4519 | F17: ST AIR SERVICES AND MAINTENANCE (PTY) LTD | G17: 426010.6 | H17: Simon Mokgola | I17: Pending | K17: Mimosa Mall Office Park (Qty: 1) | L17: =B17 -> 46171
A18: 46142 | B18: 46171 | C18: FM4036 | D18: SO4555 | E18: FM4035-FM4036 | F18: Michmat Projects | G18: 310411 | H18: Mashudu - R.O.A | I18: Pending | K18: MFAJAX-3 1250 c/w 45,00KW 4P 380V (Qty: 3), 1250 Diam Counter Flange (Qty: 6), 1250 Diam Mounting Feet (Qty: 6), 630 to 1000 NDB GREEN Neoprene Floor Mounts (Qty: 12), MAJAX-3 560 c/w 5,50KW 2P 380V (Qty: 2), 560 Diam Counter Flange (Qty: 4), 560 Diam Mounting Feet (Qty: 4), 315 to 560 NDA RED ANeoprene Floor Mounts (Qty: 8) | L18: =B18 -> 46171
A19: 46142 | B19: 46171 | C19: Pending | D19: SO4557 | E19: nan | F19: Vigeta Pty Ltd | G19: 204447 | H19: Simon Mokgola | I19: Pending | K19: 630 Diam Vertical Discharge BASE c/w 2.2kW 4P 380V (Qty: 10) | L19: =B19 -> 46171
